INFO 2024-01-19 14:25:39,510 [torch.distributed.nn.jit.instantiator:instantiator.py:<module>:21]
Created a temporary directory at /tmp/tmp8snxx4pl

INFO 2024-01-19 14:25:39,512 [torch.distributed.nn.jit.instantiator:instantiator.py:_write:76]
Writing /tmp/tmp8snxx4pl/_remote_module_non_scriptable.py

INFO 2024-01-25 22:27:36,384 [torch.distributed.nn.jit.instantiator:instantiator.py:<module>:21]
Created a temporary directory at /tmp/tmpjpf0fiob

INFO 2024-01-25 22:27:36,385 [torch.distributed.nn.jit.instantiator:instantiator.py:_write:76]
Writing /tmp/tmpjpf0fiob/_remote_module_non_scriptable.py

INFO 2024-01-25 22:42:14,660 [root:accelerator.py:_autodetect_tpu_version:216]
Unable to poll TPU GCE metadata: HTTPConnectionPool(host='metadata.google.internal', port=80): Max retries exceeded with url: /computeMetadata/v1/instance/attributes/accelerator-type (Caused by NewConnectionError('<urllib3.connection.HTTPConnection object at 0x7c0de5474df0>: Failed to establish a new connection: [Errno -2] Name or service not known'))

INFO 2024-01-25 22:46:24,894 [root:accelerator.py:_autodetect_tpu_version:216]
Unable to poll TPU GCE metadata: HTTPConnectionPool(host='metadata.google.internal', port=80): Max retries exceeded with url: /computeMetadata/v1/instance/attributes/accelerator-type (Caused by NewConnectionError('<urllib3.connection.HTTPConnection object at 0x7c0dd7be5780>: Failed to establish a new connection: [Errno -2] Name or service not known'))

INFO 2024-01-25 22:49:19,563 [root:accelerator.py:_autodetect_tpu_version:216]
Unable to poll TPU GCE metadata: HTTPConnectionPool(host='metadata.google.internal', port=80): Max retries exceeded with url: /computeMetadata/v1/instance/attributes/accelerator-type (Caused by NewConnectionError('<urllib3.connection.HTTPConnection object at 0x7c0edde157b0>: Failed to establish a new connection: [Errno -2] Name or service not known'))

INFO 2024-01-25 22:54:54,687 [root:accelerator.py:_autodetect_tpu_version:216]
Unable to poll TPU GCE metadata: HTTPConnectionPool(host='metadata.google.internal', port=80): Max retries exceeded with url: /computeMetadata/v1/instance/attributes/accelerator-type (Caused by NewConnectionError('<urllib3.connection.HTTPConnection object at 0x7c0de54753f0>: Failed to establish a new connection: [Errno -2] Name or service not known'))

INFO 2024-01-25 23:10:12,544 [root:accelerator.py:_autodetect_tpu_version:216]
Unable to poll TPU GCE metadata: HTTPConnectionPool(host='metadata.google.internal', port=80): Max retries exceeded with url: /computeMetadata/v1/instance/attributes/accelerator-type (Caused by NewConnectionError('<urllib3.connection.HTTPConnection object at 0x7c0ee442ea70>: Failed to establish a new connection: [Errno -2] Name or service not known'))

INFO 2024-01-27 20:07:08,869 [root:accelerator.py:_autodetect_tpu_version:216]
Unable to poll TPU GCE metadata: HTTPConnectionPool(host='metadata.google.internal', port=80): Max retries exceeded with url: /computeMetadata/v1/instance/attributes/accelerator-type (Caused by NewConnectionError('<urllib3.connection.HTTPConnection object at 0x7f53fa4d1a50>: Failed to establish a new connection: [Errno -2] Name or service not known'))

INFO 2024-01-27 20:12:28,549 [torch.distributed.nn.jit.instantiator:instantiator.py:<module>:21]
Created a temporary directory at /tmp/tmp1aw8dfo4

INFO 2024-01-27 20:12:28,551 [torch.distributed.nn.jit.instantiator:instantiator.py:_write:76]
Writing /tmp/tmp1aw8dfo4/_remote_module_non_scriptable.py

INFO 2024-01-27 20:46:10,451 [torch.distributed.nn.jit.instantiator:instantiator.py:<module>:21]
Created a temporary directory at /tmp/tmpseapkln2

INFO 2024-01-27 20:46:10,453 [torch.distributed.nn.jit.instantiator:instantiator.py:_write:76]
Writing /tmp/tmpseapkln2/_remote_module_non_scriptable.py

INFO 2024-01-27 21:08:09,950 [root:accelerator.py:_autodetect_tpu_version:216]
Unable to poll TPU GCE metadata: HTTPConnectionPool(host='metadata.google.internal', port=80): Max retries exceeded with url: /computeMetadata/v1/instance/attributes/accelerator-type (Caused by NewConnectionError('<urllib3.connection.HTTPConnection object at 0x7085e87bbf70>: Failed to establish a new connection: [Errno -2] Name or service not known'))

INFO 2024-01-27 21:14:26,144 [torch.distributed.nn.jit.instantiator:instantiator.py:<module>:21]
Created a temporary directory at /tmp/tmprp_yxt7y

INFO 2024-01-27 21:14:26,146 [torch.distributed.nn.jit.instantiator:instantiator.py:_write:76]
Writing /tmp/tmprp_yxt7y/_remote_module_non_scriptable.py

INFO 2024-01-27 22:01:26,910 [torch.distributed.nn.jit.instantiator:instantiator.py:<module>:21]
Created a temporary directory at /tmp/tmpxhmzfpr_

INFO 2024-01-27 22:01:26,913 [torch.distributed.nn.jit.instantiator:instantiator.py:_write:76]
Writing /tmp/tmpxhmzfpr_/_remote_module_non_scriptable.py

INFO 2024-01-27 22:05:38,627 [torch.distributed.nn.jit.instantiator:instantiator.py:<module>:21]
Created a temporary directory at /tmp/tmpn6ghtvgz

INFO 2024-01-27 22:05:38,629 [torch.distributed.nn.jit.instantiator:instantiator.py:_write:76]
Writing /tmp/tmpn6ghtvgz/_remote_module_non_scriptable.py

INFO 2024-01-27 22:11:40,124 [torch.distributed.nn.jit.instantiator:instantiator.py:<module>:21]
Created a temporary directory at /tmp/tmpdeuce9s6

INFO 2024-01-27 22:11:40,126 [torch.distributed.nn.jit.instantiator:instantiator.py:_write:76]
Writing /tmp/tmpdeuce9s6/_remote_module_non_scriptable.py

